<?xml version="1.0" encoding="UTF-8"?>
<!-- Generated by org.testng.reporters.JUnitReportReporter -->
<testsuite skipped="0" hostname="JEDUn2" name="egt.interactive.testing_framework.resources.test_ng.ExpectedExceptionNotFoundTest" tests="1" failures="0" timestamp="08 Aug 2018 07:35:52 GMT" time="0.001" errors="1">
  <testcase name="shouldGiveWrongAnswerIfNoErrorIsThrown" time="0.001" classname="egt.interactive.testing_framework.resources.test_ng.ExpectedExceptionNotFoundTest">
    <error type="org.testng.TestException" message="
Method ExpectedExceptionNotFoundTest.shouldGiveWrongAnswerIfNoErrorIsThrown()[pri:0, instance:egt.interactive.testing_framework.resources.test_ng.ExpectedExceptionNotFoundTest@5b275dab] should have thrown an exception of type class java.lang.IllegalArgumentException">
      <![CDATA[org.testng.TestException: 
Method ExpectedExceptionNotFoundTest.shouldGiveWrongAnswerIfNoErrorIsThrown()[pri:0, instance:egt.interactive.testing_framework.resources.test_ng.ExpectedExceptionNotFoundTest@5b275dab] should have thrown an exception of type class java.lang.IllegalArgumentException
at org.testng.internal.ExpectedExceptionsHolder.noException(ExpectedExceptionsHolder.java:80)
at org.testng.internal.Invoker.considerExceptions(Invoker.java:1139)
at org.testng.internal.Invoker.invokeMethod(Invoker.java:612)
at org.testng.internal.Invoker.invokeTestMethod(Invoker.java:716)
at org.testng.internal.Invoker.invokeTestMethods(Invoker.java:988)
at org.testng.internal.TestMethodWorker.invokeTestMethods(TestMethodWorker.java:125)
at org.testng.internal.TestMethodWorker.run(TestMethodWorker.java:109)
at org.testng.TestRunner.privateRun(TestRunner.java:648)
at org.testng.TestRunner.run(TestRunner.java:505)
at org.testng.SuiteRunner.runTest(SuiteRunner.java:455)
at org.testng.SuiteRunner.runSequentially(SuiteRunner.java:450)
at org.testng.SuiteRunner.privateRun(SuiteRunner.java:415)
at org.testng.SuiteRunner.run(SuiteRunner.java:364)
at org.testng.SuiteRunnerWorker.runSuite(SuiteRunnerWorker.java:52)
at org.testng.SuiteRunnerWorker.run(SuiteRunnerWorker.java:84)
at org.testng.TestNG.runSuitesSequentially(TestNG.java:1208)
at org.testng.TestNG.runSuitesLocally(TestNG.java:1137)
at org.testng.TestNG.runSuites(TestNG.java:1049)
at org.testng.TestNG.run(TestNG.java:1017)
at org.testng.remote.AbstractRemoteTestNG.run(AbstractRemoteTestNG.java:114)
at org.testng.remote.RemoteTestNG.initAndRun(RemoteTestNG.java:251)
at org.testng.remote.RemoteTestNG.main(RemoteTestNG.java:77)
]]>
    </error>
  </testcase> <!-- shouldGiveWrongAnswerIfNoErrorIsThrown -->
</testsuite> <!-- egt.interactive.testing_framework.resources.test_ng.ExpectedExceptionNotFoundTest -->
